<?xml version="1.0"?>
<robot name="simple_differential_robot">

  <joint name="base_footprint_joint" type="fixed">
    <parent link="base_link"/>
    <child link="base_footprint"/>
    <origin xyz="0 0 0" rpy="0 0 0"/>
  </joint>

  <link name="base_footprint">
    <inertial>
      <mass value="0.01"/>
      <origin xyz="0 0 0" rpy="0 0 0"/>
      <inertia ixx="1e-5" ixy="0" ixz="0" iyy="1e-5" iyz="0" izz="1e-5"/>
    </inertial>
  </link>

  <link name="base_link">
    <visual>
      <origin xyz="0 0 0.05" rpy="0 0 0"/>
      <geometry>
        <cylinder radius="0.3" length="0.1"/>
      </geometry>
      <material name="chassis_blue">
        <color rgba="0.1 0.1 0.8 1.0"/>
      </material>
    </visual>
    <collision>
      <origin xyz="0 0 0.05" rpy="0 0 0"/>
      <geometry>
        <cylinder radius="0.3" length="0.1"/>
      </geometry>
    </collision>
    <inertial>
      <mass value="4.0"/>
      <origin xyz="0 0 0.05" rpy="0 0 0"/>
      <inertia ixx="0.3016" ixy="0" ixz="0" iyy="0.3016" iyz="0" izz="0.45"/>
    </inertial>
  </link>

  <link name="left_wheel_link">
    <visual>
      <origin xyz="0 0 0" rpy="1.5708 0 0"/> 
      <geometry>
        <cylinder radius="0.1" length="0.1"/>
      </geometry>
      <material name="wheel_black">
        <color rgba="0.1 0.1 0.1 1.0"/>
      </material>
    </visual>
    <collision>
      <origin xyz="0 0 0" rpy="1.5708 0 0"/>
      <geometry>
        <cylinder radius="0.1" length="0.1"/>
      </geometry>
    </collision>
    <inertial>
      <mass value="1.0"/>
      <origin xyz="0 0 0" rpy="0 0 0"/>
      <inertia ixx="0.002916" ixy="0" ixz="0" iyy="0.002916" iyz="0" izz="0.005"/>
    </inertial>
  </link>

  <joint name="left_wheel_joint" type="continuous">
    <parent link="base_link"/>
    <child link="left_wheel_link"/>
    <origin xyz="0 0.35 0.1" rpy="0 0 0"/> 
    <axis xyz="0 1 0"/>
    <limit effort="100" velocity="10"/> 
  </joint>

  <link name="right_wheel_link">
    <visual>
      <origin xyz="0 0 0" rpy="1.5708 0 0"/>
      <geometry>
        <cylinder radius="0.1" length="0.1"/>
      </geometry>
      <material name="wheel_black">
        <color rgba="0.1 0.1 0.1 1.0"/>
      </material>
    </visual>
    <collision>
      <origin xyz="0 0 0" rpy="1.5708 0 0"/>
      <geometry>
        <cylinder radius="0.1" length="0.1"/>
      </geometry>
    </collision>
    <inertial>
      <mass value="1.0"/>
      <origin xyz="0 0 0" rpy="0 0 0"/>
      <inertia ixx="0.002916" ixy="0" ixz="0" iyy="0.002916" iyz="0" izz="0.005"/>
    </inertial>
  </link>

  <joint name="right_wheel_joint" type="continuous">
    <parent link="base_link"/>
    <child link="right_wheel_link"/>
    <origin xyz="0 -0.35 0.1" rpy="0 0 0"/>
    <axis xyz="0 1 0"/>
    <limit effort="100" velocity="10"/>
  </joint>

  <link name="lidar_link">
    <visual>
      <origin xyz="0 0 0" rpy="0 0 0"/>
      <geometry>
        <cylinder radius="0.1" length="0.1"/>
      </geometry>
      <material name="red">
        <color rgba="0.8 0.2 0.2 1.0"/>
      </material>
    </visual>
    <collision>
      <origin xyz="0.0 0.0 0.0" rpy="0.0 0.0 0.0"/>
      <geometry>
        <cylinder radius="0.01" length="0.01"/>
      </geometry>
    </collision>
    <inertial>
      <origin xyz="0 0 0" rpy="0 0 0"/>
      <mass value="0.3"/>
      <inertia ixx="0.000775" ixy="0" ixz="0" iyy="0.000775" iyz="0" izz="0.0015"/> 
    </inertial>
  </link>

  <joint name="lidar_joint" type="fixed">
    <parent link="base_link"/>
    <child link="lidar_link"/>
    <origin xyz="0 0 0.1" rpy="0 0 0"/>
  </joint>
  
  <link name="imu_link">
    <visual>
      <origin xyz="0 0 0" rpy="0 0 0"/>
      <geometry>
        <box size="0.05 0.05 0.02"/>
      </geometry>
      <material name="green">
        <color rgba="0.2 0.8 0.2 1.0"/>
      </material>
    </visual>
    
    <collision>
      <origin xyz="0 0 0" rpy="0 0 0"/>
      <geometry>
        <box size="0.05 0.05 0.02"/>
      </geometry>
    </collision>
    
    <inertial>
      <origin xyz="0 0 0" rpy="0 0 0"/>
      <mass value="0.1"/>
      <inertia ixx="0.000024" ixy="0.0" ixz="0.0" iyy="0.000024" iyz="0.0" izz="0.000042"/>
    </inertial>
  </link>
    
  <joint name="imu_joint" type="fixed">
    <parent link="base_link"/>
    <child link="imu_link"/>
    <origin xyz="0 0 0.12" rpy="0 0 0"/>
  </joint>


  <gazebo>
    <plugin
        filename="gz-sim-diff-drive-system"
        name="gz::sim::systems::DiffDrive">
        <topic>/cmd_vel</topic>
        
        <left_joint>left_wheel_joint</left_joint>
        <right_joint>right_wheel_joint</right_joint>

        <wheel_separation>0.7</wheel_separation> 
        <wheel_radius>0.1</wheel_radius> 

        <max_linear_velocity>1.0</max_linear_velocity>
        <min_linear_velocity>-1.0</min_linear_velocity>
        <max_angular_velocity>2.0</max_angular_velocity>
        <min_angular_velocity>-2.0</min_angular_velocity>
        
        <odom_topic>/wheel_encoder/odom</odom_topic> 
        <frame_id>odom</frame_id>
        <child_frame_id>base_link</child_frame_id>
        <odom_publish_frequency>60</odom_publish_frequency>
    </plugin>
  </gazebo>

  <gazebo>
    <plugin
        filename="gz-sim-joint-state-publisher-system"
        name="gz::sim::systems::JointStatePublisher">
        <topic>joint_states</topic>
        <joint_name>left_wheel_joint</joint_name>
        <joint_name>right_wheel_joint</joint_name>
    </plugin>
  </gazebo>
  
  <gazebo>
      <plugin filename="libignition-gazebo-imu-system"
          name="ignition::gazebo::systems::Imu">
      </plugin>
  </gazebo>
  <gazebo reference="imu_link">
      <sensor name="imu_sensor" type="imu">
          <always_on>1</always_on>
          <update_rate>100</update_rate>
          <visualize>true</visualize>
          <topic>/imu_data</topic>
      </sensor>
  </gazebo>

  <gazebo reference="lidar_link">
    <sensor type="gpu_lidar" name="lidar_sensor">
        <always_on>1</always_on>
        <visualize>true</visualize>
        <update_rate>10</update_rate>
        <topic>/scan</topic>
        <lidar>
            <scan>
                <horizontal>
                    <samples>360</samples>
                    <resolution>1</resolution>
                    <min_angle>-3.14</min_angle>
                    <max_angle>3.14</max_angle>
                </horizontal>
                <vertical>
                    <samples>1</samples>
                    <resolution>1</resolution>
                    <min_angle>0</min_angle>
                    <max_angle>0</max_angle>
                </vertical>
            </scan>
            <range>
                <min>0.1</min>
                <max>10.0</max>
                <resolution>0.01</resolution>
            </range>  
            <noise>
                <type>gaussian</type>
                <mean>0.0</mean>
                <stddev>0.01</stddev>
            </noise>
        </lidar>
    </sensor>
  </gazebo>

</robot>




